[32m2024-04-25 14:19:18 +0700[0m - dagster - [34mDEBUG[0m - __ASSET_JOB - 4b88f327-2158-4622-bc71-e373083c81b6 - 644644 - LOGS_CAPTURED - Started capturing logs in process (pid: 644644).
[32m2024-04-25 14:19:18 +0700[0m - dagster - [34mDEBUG[0m - __ASSET_JOB - 4b88f327-2158-4622-bc71-e373083c81b6 - 644644 - order_count_chart - STEP_START - Started execution of step "order_count_chart".
[32m2024-04-25 14:19:19 +0700[0m - dagster - [34mERROR[0m - [31m__ASSET_JOB - 4b88f327-2158-4622-bc71-e373083c81b6 - 644644 - order_count_chart - STEP_FAILURE - Execution of step "order_count_chart" failed.

dagster._core.errors.DagsterExecutionStepExecutionError: Error occurred while executing op "order_count_chart"::

NameError: name 'MetadataValue' is not defined

Stack Trace:
  File "/home/bui.van.thuong@sun-asterisk.com/.local/lib/python3.10/site-packages/dagster/_core/execution/plan/utils.py", line 54, in op_execution_error_boundary
    yield
  File "/home/bui.van.thuong@sun-asterisk.com/.local/lib/python3.10/site-packages/dagster/_utils/__init__.py", line 464, in iterate_with_context
    next_output = next(iterator)
  File "/home/bui.van.thuong@sun-asterisk.com/.local/lib/python3.10/site-packages/dagster/_core/execution/plan/compute_generator.py", line 141, in _coerce_op_compute_fn_to_iterator
    result = invoke_compute_fn(
  File "/home/bui.van.thuong@sun-asterisk.com/.local/lib/python3.10/site-packages/dagster/_core/execution/plan/compute_generator.py", line 129, in invoke_compute_fn
    return fn(context, **args_to_pass) if context_arg_provided else fn(**args_to_pass)
  File "/home/bui.van.thuong@sun-asterisk.com/Documents/dagster_tutorial/tutorial-dbt-dagster/jaffle_shop/jaffle_dagster/jaffle_dagster/assets.py", line 49, in order_count_chart
    {"plot_url": MetadataValue.url("file://" + os.fspath(save_chart_path))}
[0m
